[*] LOGDIR = reports_auto/intent_import/20250914T194707
[PKL] intent/intent/artifacts/intent_pro_cal.pkl
Traceback (most recent call last):
  File "<stdin>", line 36, in <module>
  File "/home/youjie/projects/smart-mail-agent-ssot-pro/.venv/lib/python3.10/site-packages/joblib/numpy_pickle.py", line 749, in load
    obj = _unpickle(
  File "/home/youjie/projects/smart-mail-agent-ssot-pro/.venv/lib/python3.10/site-packages/joblib/numpy_pickle.py", line 626, in _unpickle
    obj = unpickler.load()
  File "/usr/lib/python3.10/pickle.py", line 1213, in load
    dispatch[key[0]](self)
  File "/usr/lib/python3.10/pickle.py", line 1538, in load_stack_global
    self.append(self.find_class(module, name))
  File "/usr/lib/python3.10/pickle.py", line 1582, in find_class
    return _getattribute(sys.modules[module], name)[0]
  File "/usr/lib/python3.10/pickle.py", line 331, in _getattribute
    raise AttributeError("Can't get attribute {!r} on {!r}"
AttributeError: Can't get attribute 'rules_feat' on <module '__main__' (built-in)>

During handling of the above exception, another exception occurred:

Traceback (most recent call last):
  File "<stdin>", line 38, in <module>
  File "/usr/lib/python3.10/pathlib.py", line 1154, in write_text
    with self.open(mode='w', encoding=encoding, errors=errors, newline=newline) as f:
  File "/usr/lib/python3.10/pathlib.py", line 1119, in open
    return self._accessor.open(self, mode, buffering, encoding, errors,
FileNotFoundError: [Errno 2] No such file or directory: 'reports_auto/intent_import/_missing/last_trace.txt'
